<?xml version="1.0" ?>
<!-- =================================================================================== -->
<!-- |    This document was autogenerated by xacro from jetduinobot.urdf.xacro         | -->
<!-- |    EDITING THIS FILE BY HAND IS NOT RECOMMENDED                                 | -->
<!-- =================================================================================== -->
<!--
  The complete jetduinobot library of xacros for easy reference
 -->
<robot name="jetduinobot" xmlns:xacro="http://ros.org/wiki/xacro">
  <!-- General -->
  <!-- 
    These properties must be observed by any machine
    that wants to be defined as a jetduinobot. Refer
    to the REP for more details.
    
    http://www.ros.org/reps/rep-0119.html
   -->
  <!-- Bases -->
  <link name="world_link"/>
  <link name="base_link">
    <visual>
      <geometry>
        <box size="0.225 0.185 0.15"/>
      </geometry>
      <material name="silver"/>
    </visual>
    <collision>
      <geometry>
        <box size="0.225 0.185 0.15"/>
      </geometry>
    </collision>
    <inertial>
      <mass value="0.5"/>
      <inertia ixx="0.015" ixy="0" ixz="0" iyy="0.0375" iyz="0" izz="0.0375"/>
    </inertial>
  </link>
  <joint name="base_joint" type="fixed">
    <parent link="world_link"/>
    <child link="base_link"/>
    <origin rpy="0 0 0" xyz="0 0 0"/>
  </joint>
  <!-- rear wheels -->
  <!-- right rear wheel -->
  <link name="right_rear_wheel_link">
    <visual>
      <geometry>
        <mesh filename="package://jetduinobot_description/meshes/wheel_tread.dae" scale="3 3 3"/>
      </geometry>
    </visual>
    <collision>
      <geometry>
        <cylinder length="0.025" radius="0.029"/>
      </geometry>
    </collision>
    <inertial>
      <mass value="0.05"/>
      <inertia ixx="5.1458e-5" ixy="0" ixz="0" iyy="5.1458e-5" iyz="0" izz="6.125e-5"/>
    </inertial>
  </link>
  <joint name="right_rear_wheel_joint" type="continuous">
    <axis xyz="0 0 1"/>
    <parent link="base_link"/>
    <child link="right_rear_wheel_link"/>
    <origin rpy="-1.5708 0 0" xyz="-1.0825 -0.074 -0.062"/>
  </joint>
  <!-- left rear wheel -->
  <link name="left_rear_wheel_link">
    <visual>
      <geometry>
        <mesh filename="package://jetduinobot_description/meshes/wheel_tread.dae" />
      </geometry>
      <material name="black"/>
    </visual>
    <collision>
      <geometry>
        <cylinder length="0.025" radius="0.029"/>
      </geometry>
    </collision>
    <inertial>
      <mass value="0.1"/>
      <inertia ixx="5.1458e-5" ixy="0" ixz="0" iyy="5.1458e-5" iyz="0" izz="6.125e-5"/>
    </inertial>
  </link>
  <joint name="left_rear_wheel_joint" type="continuous">
    <axis xyz="0 0 1"/>
    <parent link="base_link"/>
    <child link="left_rear_wheel_link"/>
    <origin rpy="-1.5708 0 0" xyz="-0.0825 0.074 -0.062"/>
  </joint>
  <!-- front wheels -->
  <!-- right front wheel -->
  <link name="right_front_wheel_link">
    <visual>
      <geometry>
        <mesh filename="package://jetduinobot_description/meshes/wheel_tread.dae" />
      </geometry>
      <material name="black"/>
    </visual>
    <collision>
      <geometry>
        <cylinder length="0.025" radius="0.029"/>
      </geometry>
    </collision>
    <inertial>
      <mass value="0.05"/>
      <inertia ixx="5.1458e-5" ixy="0" ixz="0" iyy="5.1458e-5" iyz="0" izz="6.125e-5"/>
    </inertial>
  </link>
  <joint name="right_front_wheel_joint" type="continuous">
    <axis xyz="0 0 1"/>
    <parent link="base_link"/>
    <child link="right_front_wheel_link"/>
    <origin rpy="-1.5708 0 0" xyz="0.0475 -0.074 -0.062"/>
  </joint>
  <!-- left front wheel -->
  <link name="left_front_wheel_link">
    <visual>
      <geometry>
        <mesh filename="package://jetduinobot_description/meshes/wheel_tread.dae" scale="1 1 1"/>
      </geometry>
      <material name="black"/>
    </visual>
    <collision>
      <geometry>
        <cylinder length="0.025" radius="0.029"/>
      </geometry>
    </collision>
    <inertial>
      <mass value="0.1"/>
      <inertia ixx="5.1458e-5" ixy="0" ixz="0" iyy="5.1458e-5" iyz="0" izz="6.125e-5"/>
    </inertial>
  </link>
  <joint name="left_front_wheel_joint" type="continuous">
    <axis xyz="0 0 1"/>
    <parent link="base_link"/>
    <child link="left_front_wheel_link"/>
    <origin rpy="-1.5708 0 0" xyz="0.0475 0.074 -0.062"/>
  </joint>
  <gazebo>
    <plugin filename="libgazebo_ros_skid_steer_drive.so" name="skid_steer_drive_controller">
      <leftFrontJoint>left_front_wheel_joint</leftFrontJoint>
      <rightFrontJoint>right_front_wheel_joint</rightFrontJoint>
      <leftRearJoint>left_rear_wheel_joint</leftRearJoint>
      <rightRearJoint>right_rear_wheel_joint</rightRearJoint>
      <wheelSeparation>0.148</wheelSeparation>
      <wheelDiameter>0.065</wheelDiameter>
      <robotBaseFrame>base_link</robotBaseFrame>
      <torque>20</torque>
    </plugin>
  </gazebo>
  <!-- Stacks -->
  <!-- 3D Sensors -->
</robot>
